ERROR:root:Except on get_username_by_user_id
Traceback (most recent call last):
  File "C:\Users\HP\AppData\Local\Programs\Python\Python36-32\lib\site-packages\urllib3\connection.py", line 159, in _new_conn
    (self._dns_host, self.port), self.timeout, **extra_kw)
  File "C:\Users\HP\AppData\Local\Programs\Python\Python36-32\lib\site-packages\urllib3\util\connection.py", line 80, in create_connection
    raise err
  File "C:\Users\HP\AppData\Local\Programs\Python\Python36-32\lib\site-packages\urllib3\util\connection.py", line 70, in create_connection
    sock.connect(sa)
TimeoutError: [WinError 10060] A connection attempt failed because the connected party did not properly respond after a period of time, or established connection failed because connected host has failed to respond

During handling of the above exception, another exception occurred:

Traceback (most recent call last):
  File "C:\Users\HP\AppData\Local\Programs\Python\Python36-32\lib\site-packages\urllib3\connectionpool.py", line 600, in urlopen
    chunked=chunked)
  File "C:\Users\HP\AppData\Local\Programs\Python\Python36-32\lib\site-packages\urllib3\connectionpool.py", line 343, in _make_request
    self._validate_conn(conn)
  File "C:\Users\HP\AppData\Local\Programs\Python\Python36-32\lib\site-packages\urllib3\connectionpool.py", line 839, in _validate_conn
    conn.connect()
  File "C:\Users\HP\AppData\Local\Programs\Python\Python36-32\lib\site-packages\urllib3\connection.py", line 301, in connect
    conn = self._new_conn()
  File "C:\Users\HP\AppData\Local\Programs\Python\Python36-32\lib\site-packages\urllib3\connection.py", line 168, in _new_conn
    self, "Failed to establish a new connection: %s" % e)
urllib3.exceptions.NewConnectionError: <urllib3.connection.VerifiedHTTPSConnection object at 0x031265D0>: Failed to establish a new connection: [WinError 10060] A connection attempt failed because the connected party did not properly respond after a period of time, or established connection failed because connected host has failed to respond

During handling of the above exception, another exception occurred:

Traceback (most recent call last):
  File "C:\Users\HP\AppData\Local\Programs\Python\Python36-32\lib\site-packages\requests\adapters.py", line 449, in send
    timeout=timeout
  File "C:\Users\HP\AppData\Local\Programs\Python\Python36-32\lib\site-packages\urllib3\connectionpool.py", line 638, in urlopen
    _stacktrace=sys.exc_info()[2])
  File "C:\Users\HP\AppData\Local\Programs\Python\Python36-32\lib\site-packages\urllib3\util\retry.py", line 398, in increment
    raise MaxRetryError(_pool, url, error or ResponseError(cause))
urllib3.exceptions.MaxRetryError: HTTPSConnectionPool(host='i.instagram.com', port=443): Max retries exceeded with url: /api/v1/users/4390068868/info/ (Caused by NewConnectionError('<urllib3.connection.VerifiedHTTPSConnection object at 0x031265D0>: Failed to establish a new connection: [WinError 10060] A connection attempt failed because the connected party did not properly respond after a period of time, or established connection failed because connected host has failed to respond',))

During handling of the above exception, another exception occurred:

Traceback (most recent call last):
  File "C:\Users\HP\Desktop\instabot\instabot.py-master\src\instabot.py", line 435, in get_username_by_user_id
    r = self.s.get(url_info, headers="")
  File "C:\Users\HP\AppData\Local\Programs\Python\Python36-32\lib\site-packages\requests\sessions.py", line 546, in get
    return self.request('GET', url, **kwargs)
  File "C:\Users\HP\AppData\Local\Programs\Python\Python36-32\lib\site-packages\requests\sessions.py", line 533, in request
    resp = self.send(prep, **send_kwargs)
  File "C:\Users\HP\AppData\Local\Programs\Python\Python36-32\lib\site-packages\requests\sessions.py", line 646, in send
    r = adapter.send(request, **kwargs)
  File "C:\Users\HP\AppData\Local\Programs\Python\Python36-32\lib\site-packages\requests\adapters.py", line 516, in send
    raise ConnectionError(e, request=request)
requests.exceptions.ConnectionError: HTTPSConnectionPool(host='i.instagram.com', port=443): Max retries exceeded with url: /api/v1/users/4390068868/info/ (Caused by NewConnectionError('<urllib3.connection.VerifiedHTTPSConnection object at 0x031265D0>: Failed to establish a new connection: [WinError 10060] A connection attempt failed because the connected party did not properly respond after a period of time, or established connection failed because connected host has failed to respond',))
ERROR:root:Except on follow!
Traceback (most recent call last):
  File "C:\Users\HP\Desktop\instabot\instabot.py-master\src\instabot.py", line 646, in follow
    insert_username(self, user_id=user_id, username=username)
  File "C:\Users\HP\Desktop\instabot\instabot.py-master\src\sql_updates.py", line 81, in insert_username
    VALUES('"+user_id+"','"+username+"','"+ str(now) +"')")
TypeError: must be str, not bool
